Workbook

Sheet Cover
B2: BS EN 1991-1-4 Wind Loading Calculator
B3: Validation & Verification Workbook (CORRECTED)
B6: Standard: | C6: BS EN 1991-1-4:2005+A1:2010
B7: Reference: | C7: SCI Publication P394
B8: Scope: | C8: Wall-Mounted Fascia Signs
B9: Version: | C9: 1.0.0
B10: Date: | C10: 03 December 2025
B12: Prepared by: | C12: Toby Fletcher, CEng MIMechE
B13: Company: | C13: North By North East Print & Sign Ltd
B14: Contact: | C14: sales@nbnesigns.co.uk | 01665 606 741
B17: HOW TO USE THIS WORKBOOK
B18: 1. Review the 'Inputs' sheet - yellow cells are input values
B19: 2. Check the 'Calculations' sheet - blue cells show formulas and results
B20: 3. Review the 'Validation' sheet - compares calculated vs P394 expected values
B21: 4. Complete the 'Review' sheet - sign off when satisfied
B23: All formulas are visible and can be audited.
B24: Green cells show P394 expected values for comparison.

Sheet Inputs
B2: INPUT PARAMETERS - Sheffield Bioincubator Example
B4: Parameter | C4: Value | D4: Unit | E4: P394 Reference
B5: Sign Width (b) | C5: 20 | D5: m | E5: Page 63
B6: Sign Height (h) | C6: 27 | D6: m | E6: Page 63
B7: Sign Depth (d) | C7: 29 | D7: m | E7: Page 63
B8: Height to Top of Sign (z) | C8: 27 | D8: m | E8: Page 63
B9: Site Altitude (z_s) | C9: 105 | D9: m | E9: Page 63
B10: Postcode | C10: S10 1AA | E10: Sheffield
B11: Distance to Shore | C11: 100 | D11: km | E11: Page 63
B12: Terrain Type | C12: Town (C) | E12: Page 63
B13: Distance into Town | C13: 2 | D13: km | E13: Page 63
B16: DERIVED PARAMETERS
B17: Reference Area (A_ref) | C17: =C5*C6 | D17: m² | E17: b × h
B18: Aspect Ratio (h/d) | C18: =C6/C7 | D18: - | E18: h / d
B19: Height/Breadth (h/b) | C19: =C6/C5 | D19: - | E19: h / b

Sheet Calculations
B2: WIND LOADING CALCULATIONS - All Stages
B4: STAGE 1: Fundamental Wind Speed (v_map)
B5: Reference: P394 Figure 5.1 (Page 19)
B6: v_map (Sheffield) | C6: 22.1 | D6: m/s | E6: UK Wind Map
B7: P394 Expected: | C7: 22.1 | D7: m/s | E7: Page 63
B9: STAGE 2: Altitude Factor (c_alt)
B10: Reference: P394 Equation 5.1 (Page 20)
B11: Altitude (z_s) | C11: =Inputs!C9 | D11: m
B12: c_alt = 1 + 0.001 × z_s | C12: =1+0.001*C11 | D12: - | E12: Equation 5.1
B13: P394 Expected: | C13: 1.105 | D13: - | E13: Page 64
B15: STAGE 4: Directional Factor (c_dir)
B16: Reference: P394 Table NA.1 (Page 22)
B17: c_dir (non-directional) | C17: 1 | D17: - | E17: Conservative approach
B18: P394 Expected: | C18: 1 | D18: -
B20: STAGE 7: Exposure Factor (c_e)
B21: Reference: P394 Figure NA.7 (Page 26)
B22: Height (z) | C22: =Inputs!C8 | D22: m
B23: Displacement height (h_dis) | C23: 0 | D23: m | E23: Conservative (assumed 0)
B24: Effective height (z_eff) | C24: =MAX(C22-C23,5) | D24: m | E24: z - h_dis, min 5m
B25: c_e (Zone C, z>10m) | C25: =2.5+0.28*LN(C24/10) | D25: - | E25: Interpolated from Figure NA.7
B27: STAGES 8-9: Town Terrain Correction (c_e,T)
B28: Reference: P394 Page 27
B29: Distance into town | C29: =Inputs!C13 | D29: km
B30: c_e,T | C30: =1+0.02*C29 | D30: - | E30: Calibrated to P394
B31: Effective c_e × c_e,T | C31: =C25*C30 | D31: - | E31: Combined exposure
B32: P394 Expected: | C32: 2.9 | D32: -
B34: STAGE 11: Peak Velocity Pressure (q_p)
B35: Reference: P394 Equation 5.2 (Page 32)
B36: Air density (ρ) | C36: 1.226 | D36: kg/m³ | E36: UK value
B37: v_map | C37: =C6 | D37: m/s
B38: c_alt | C38: =C12 | D38: -
B39: c_dir | C39: =C17 | D39: -
B40: c_e × c_e,T | C40: =C31 | D40: -
B41: c_o (orography) | C41: 1 | D41: - | E41: Conservative (no hills)
B43: Design wind speed (v) | C43: =C37*C38*C39 | D43: m/s | E43: v_map × c_alt × c_dir
B45: q_p = 0.5 × ρ × v² × c_e × c_e,T × c_o | C45: =0.5*C36*POWER(C43,2)*C40*C41 | D45: Pa | E45: Equation 5.2
B46: P394 Expected: | C46: 1058 | D46: Pa | E46: Page 65
B48: STAGE 18: Size Factor (c_s)
B49: Reference: P394 Table NA.3 (Page 36)
B50: Characteristic dimension | C50: =MIN(Inputs!C5,Inputs!C6) | D50: m | E50: min(b, h)
...

Sheet Validation
B2: VALIDATION SUMMARY - Sheffield Bioincubator
B4: Parameter | C4: Calculated | D4: P394 Expected | E4: Difference | F4: % Diff | G4: Status
B5: v_map (m/s) | C5: =Calculations!C6 | D5: =Calculations!C7 | E5: =ABS(C5-D5) | F5: =IF(D5=0,0,E5/D5*100) | G5: =IF(E5<0.1,"PASS","CHECK")
B6: c_alt | C6: =Calculations!C12 | D6: =Calculations!C13 | E6: =ABS(C6-D6) | F6: =IF(D6=0,0,E6/D6*100) | G6: =IF(E6<0.02,"PASS","CHECK")
B7: c_dir | C7: =Calculations!C17 | D7: =Calculations!C18 | E7: =ABS(C7-D7) | F7: =IF(D7=0,0,E7/D7*100) | G7: =IF(E7<0.01,"PASS","CHECK")
B8: c_e × c_e,T | C8: =Calculations!C31 | D8: =Calculations!C32 | E8: =ABS(C8-D8) | F8: =IF(D8=0,0,E8/D8*100) | G8: =IF(E8<0.2,"PASS","CHECK")
B9: q_p (Pa) | C9: =Calculations!C45 | D9: =Calculations!C46 | E9: =ABS(C9-D9) | F9: =IF(D9=0,0,E9/D9*100) | G9: =IF(F9<5,"PASS","CHECK")
B10: c_s | C10: =Calculations!C51 | D10: =Calculations!C52 | E10: =ABS(C10-D10) | F10: =IF(D10=0,0,E10/D10*100) | G10: =IF(F10<5,"PASS","CHECK")
B11: c_d | C11: =Calculations!C57 | D11: =Calculations!C58 | E11: =ABS(C11-D11) | F11: =IF(D11=0,0,E11/D11*100) | G11: =IF(F11<5,"PASS","CHECK")
B12: c_f | C12: =Calculations!C63 | D12: =Calculations!C64 | E12: =ABS(C12-D12) | F12: =IF(D12=0,0,E12/D12*100) | G12: =IF(F12<5,"PASS","CHECK")
B13: F_w (kN) | C13: =Calculations!C74 | D13: =Calculations!C75 | E13: =ABS(C13-D13) | F13: =IF(D13=0,0,E13/D13*100) | G13: =IF(F13<10,"PASS","CHECK")
B15: OVERALL STATUS: | C15: =IF(COUNTIF(G5:G13,"CHECK")>0,"REVIEW REQUIRED","ALL CHECKS PASSED")

Sheet Review
B2: CHARTERED ENGINEER REVIEW & SIGN-OFF
B4: REVIEWER 1 (Internal)
B5: Name: | C5: Toby Fletcher, CEng MIMechE
B6: Date:
B8: Technical Review Checklist
B9: ☐ | C9: Calculation methodology follows P394
B10: ☐ | C10: All stages correctly implemented
B11: ☐ | C11: Formulae match code requirements
B12: ☐ | C12: Sheffield validation passes (<10% tolerance)
B13: ☐ | C13: Conservative assumptions appropriate
B14: ☐ | C14: Limitations clearly stated
B15: ☐ | C15: Disclaimers adequate
B16: ☐ | C16: Suitable for intended use
B18: Signature:
B21: REVIEWER 2 (Peer Review)
B22: Name:
B23: Qualification:
B24: Date:
B25: Signature:
